Workbook

Sheet README
A1: HIL Benchmark Library v1.0
A3: Purpose | B3: Comprehensive benchmark library for Harness-Level Intelligence across C, I, O, DI, SA, U, HG ladder, VR and HDS.
A4: Framework basis | B4: Unified Intelligence / HIL Framework v1.5.1 (memory-integrated, delivered-correct delegation)
A5: Native task specifications | B5: 666
A6: Delegation T×H cells | B6: 960
A7: External benchmark registry | B7: 24
A8: Long-term memory | B8: Embedded inside Individual Intelligence I; long context alone does not certify I1.
A9: Primary DI reliability | B9: S_del(T,H)=P(delivered AND external verifier pass)
A10: Outcome integrity | B10: Report false completion, held-back invalid, and false rejection separately.
A11: Pair score | B11: HLIS(m,h)=weighted geometric mean of cumulative A_d achievements.
A12: Model characterization | B12: Same frozen model across HG0→HGΩ produces Harness Scaling Curve; curve is primary.
A13: Binding rule | B13: bound / band-only / specification-only; bound starter instances are development-only, not hidden certification.

Sheet Dashboard
A1: HIL Benchmark Library — Coverage Dashboard
A3: Metric | B3: Value | D3: Suite | E3: Task specs | G3: Coordinate | H3: Meaning
A4: Total native task specs | B4: =COUNTA(Task_Catalog!$A$2:$A$667) | D4: C-Bench | E4: =COUNTIF(Task_Catalog!$D$2:$D$667,D4) | G4: C | H4: Cognitive problem solving / reasoning
A5: Bound development instances | B5: =COUNTIF(Task_Catalog!$Z$2:$Z$667,"bound") | D5: I-Bench | E5: =COUNTIF(Task_Catalog!$D$2:$D$667,D5) | G5: I | H5: Persistent individual evolution; long-term memory embedded
A6: Specification-only tasks | B6: =COUNTIF(Task_Catalog!$Z$2:$Z$667,"specification-only") | D6: O-Bench | E6: =COUNTIF(Task_Catalog!$D$2:$D$667,D6) | G6: O | H6: Collective/organizational intelligence
A7: Delegation T×H cells | B7: 960 | D7: DI-Bench | E7: =COUNTIF(Task_Catalog!$D$2:$D$667,D7) | G7: DI | H7: Task difficulty × human cognitive intervention
A8: External benchmark entries | B8: 24 | D8: SA-Bench | E8: =COUNTIF(Task_Catalog!$D$2:$D$667,D8) | G8: SA | H8: Evidence-grounded self-modeling
A9: Harness generations | B9: 8 | D9: U-Bench | E9: =COUNTIF(Task_Catalog!$D$2:$D$667,D9) | G9: U | H9: Cumulative gated Unified Intelligence
A10: Unified gates | B10: 8 | D10: HIL-Ladder | E10: =COUNTIF(Task_Catalog!$D$2:$D$667,D10) | G10: HIL | H10: Harness Scaling Curve / model-harness response
D11: VR-Bench | E11: =COUNTIF(Task_Catalog!$D$2:$D$667,D11) | G11: VR | H11: Verification responsiveness
D12: HDS-Bench | E12: =COUNTIF(Task_Catalog!$D$2:$D$667,D12) | G12: HDS | H12: Harness design ability under external evaluation

Sheet Suite_Map
A1: Suite | B1: Core construct | C1: Coverage | D1: Formal requirement | E1: Primary outputs
A2: C-Bench | B2: Cognitive Intelligence C | C2: C0-CΩ × 8 domains × 2 variants | D2: Minimal harness; external correctness/robustness; no persistence credit | E2: A_C, domain profile
A3: I-Bench | B3: Individual Intelligence I | C3: I0-IΩ, 7 facets/level × 2 variants | D3: Longitudinal; I1+ restart; I2+ learning; I3+ external promotion | E3: A_I, memory diagnostics, retention
A4: O-Bench | B4: Organizational Intelligence O | C4: O0-OΩ, 6 facets/level × 2 variants | D4: Real roles/processes; persistent org state; evaluator/promoter separation | E4: A_O, coordination/reorg/discovery
A5: DI-Bench | B5: Delegation Intelligence DI | C5: T0-TΩ × 10 families × 2 variants × H0-H5 | D5: External verifier + delivery status + intervention/CID logs | E5: S_del(T,H), F(H,p), FC/FR, HCIL
A6: SA-Bench | B6: Self-Awareness SA | C6: SA0-SAΩ, 6 facets/level × 2 variants | D6: Grounded machine state; no self-report-only credit | E6: A_SA, calibration/error profile
A7: U-Bench | B7: Unified Intelligence U | C7: U0-UΩ × 4 gate cases | D7: All lower retention plus every coordinate gate | E7: U*, bottleneck, retention
A8: HIL-Ladder | B8: Harness response | C8: HG0-HGΩ × 4 mechanism probes | D8: Same frozen model/resources/benchmark; paired where possible | E8: HSC, HIL-Level, ceiling, gain
A9: VR-Bench | B9: Verification Responsiveness | C9: 6 failure classes × 2 domains × 2 variants | D9: Accurate verifier feedback; no human help >CID1 | E9: VR
A10: HDS-Bench | B10: Harness Design Score | C10: 6 design challenges × 2 variants | D10: Frozen hidden eval; designer cannot control exam | E10: HDG/HDS

Sheet Task_Catalog
A1: task_id | B1: library_version | C1: paper_basis | D1: suite | E1: coordinate | F1: target_level | G1: harness_generation | H1: unified_target | I1: facet | J1: task_family | K1: difficulty_band | L1: variant | M1: title | N1: objective | O1: setup | P1: deliverable | Q1: success_criterion | R1: hidden_condition | S1: verifier_type | T1: human_intervention_budget | U1: max_cid | V1: reliability_target | W1: repetitions | X1: paired_design | Y1: retention_requirements | Z1: binding_status | AA1: certification_ready | AB1: hidden_asset_requirement | AC1: resource_envelope | AD1: requires_persistent_state | AE1: requires_multi_agent | AF1: requires_learning | AG1: requires_self_modification | AH1: dynamic_environment | AI1: primary_metrics | AJ1: secondary_metrics | AK1: leakage_control | AL1: split | AM1: generator_ref
A2: C-C0-GENE-A | B2: 1.0 | C2: Unified Intelligence / HIL Framework v1.5.1 (memory-integrated, delivered-correct delegation) | D2: C-Bench | E2: C | F2: C0 | G2: HG0 | I2: general_reasoning | J2: general_reasoning | K2: T0 | L2: A | M2: C0 Reactive — General Reasoning (A) | N2: Direct pattern-conditioned response on simple problems. Domain: general reasoning. Variant A: clean controlled condition. | O2: Minimal standardized context/tools; no persistence credit. External oracle owns success. | P2: answer or executable artifact plus compact evidence record | Q2: Externally verified performance consistent with C0; isolate cognition rather than persistence/autonomy. | R2: Hidden answer key/counterexamples/perturbations appropriate to domain. | S2: independent_reference_or_deterministic | T2: H5-H4 | U2: CID0 | V2: 0.9 | W2: 40 | X2: no | Z2: bound | AA2: False | AB2: required for formal certification | AC2: HIL-R2 | AD2: False | AE2: False | AF2: False | AG2: False | AH2: False | AI2: correctness; robustness; calibration | AJ2: tokens; latency; contamination notes | AK2: hidden/sealed assets; candidate cannot write verifier/acceptance criteria | AL2: development-bound
A3: C-C0-GENE-B | B3: 1.0 | C3: Unified Intelligence / HIL Framework v1.5.1 (memory-integrated, delivered-correct delegation) | D3: C-Bench | E3: C | F3: C0 | G3: HG0 | I3: general_reasoning | J3: general_reasoning | K3: T0 | L3: B | M3: C0 Reactive — General Reasoning (B) | N3: Direct pattern-conditioned response on simple problems. Domain: general reasoning. Variant B: distribution shift/distractors. | O3: Minimal standardized context/tools; no persistence credit. External oracle owns success. | P3: answer or executable artifact plus compact evidence record | Q3: Externally verified performance consistent with C0; isolate cognition rather than persistence/autonomy. | R3: Hidden answer key/counterexamples/perturbations appropriate to domain. | S3: independent_reference_or_deterministic | T3: H5-H4 | U3: CID0 | V3: 0.9 | W3: 40 | X3: no | Z3: specification-only | AA3: False | AB3: required for formal certification | AC3: HIL-R2 | AD3: False | AE3: False | AF3: False | AG3: False | AH3: False | AI3: correctness; robustness; calibration | AJ3: tokens; latency; contamination notes | AK3: hidden/sealed assets; candidate cannot write verifier/acceptance criteria | AL3: certification-spec
A4: C-C0-SCIE-A | B4: 1.0 | C4: Unified Intelligence / HIL Framework v1.5.1 (memory-integrated, delivered-correct delegation) | D4: C-Bench | E4: C | F4: C0 | G4: HG0 | I4: scientific_reasoning | J4: scientific_reasoning | K4: T0 | L4: A | M4: C0 Reactive — Scientific Reasoning (A) | N4: Direct pattern-conditioned response on simple problems. Domain: scientific reasoning. Variant A: clean controlled condition. | O4: Minimal standardized context/tools; no persistence credit. External oracle owns success. | P4: answer or executable artifact plus compact evidence record | Q4: Externally verified performance consistent with C0; isolate cognition rather than persistence/autonomy. | R4: Hidden answer key/counterexamples/perturbations appropriate to domain. | S4: independent_reference_or_deterministic | T4: H5-H4 | U4: CID0 | V4: 0.9 | W4: 40 | X4: no | Z4: specification-only | AA4: False | AB4: required for formal certification | AC4: HIL-R2 | AD4: False | AE4: False | AF4: False | AG4: False | AH4: False | AI4: correctness; robustness; calibration | AJ4: tokens; latency; contamination notes | AK4: hidden/sealed assets; candidate cannot write verifier/acceptance criteria | AL4: certification-spec
A5: C-C0-SCIE-B | B5: 1.0 | C5: Unified Intelligence / HIL Framework v1.5.1 (memory-integrated, delivered-correct delegation) | D5: C-Bench | E5: C | F5: C0 | G5: HG0 | I5: scientific_reasoning | J5: scientific_reasoning | K5: T0 | L5: B | M5: C0 Reactive — Scientific Reasoning (B) | N5: Direct pattern-conditioned response on simple problems. Domain: scientific reasoning. Variant B: distribution shift/distractors. | O5: Minimal standardized context/tools; no persistence credit. External oracle owns success. | P5: answer or executable artifact plus compact evidence record | Q5: Externally verified performance consistent with C0; isolate cognition rather than persistence/autonomy. | R5: Hidden answer key/counterexamples/perturbations appropriate to domain. | S5: independent_reference_or_deterministic | T5: H5-H4 | U5: CID0 | V5: 0.9 | W5: 40 | X5: no | Z5: specification-only | AA5: False | AB5: required for formal certification | AC5: HIL-R2 | AD5: False | AE5: False | AF5: False | AG5: False | AH5: False | AI5: correctness; robustness; calibration | AJ5: tokens; latency; contamination notes | AK5: hidden/sealed assets; candidate cannot write verifier/acceptance criteria | AL5: certification-spec
A6: C-C0-ADVA-A | B6: 1.0 | C6: Unified Intelligence / HIL Framework v1.5.1 (memory-integrated, delivered-correct delegation) | D6: C-Bench | E6: C | F6: C0 | G6: HG0 | I6: advanced_mathematics | J6: advanced_mathematics | K6: T0 | L6: A | M6: C0 Reactive — Advanced Mathematics (A) | N6: Direct pattern-conditioned response on simple problems. Domain: advanced mathematics. Variant A: clean controlled condition. | O6: Minimal standardized context/tools; no persistence credit. External oracle owns success. | P6: answer or executable artifact plus compact evidence record | Q6: Externally verified performance consistent with C0; isolate cognition rather than persistence/autonomy. | R6: Hidden answer key/counterexamples/perturbations appropriate to domain. | S6: independent_reference_or_deterministic | T6: H5-H4 | U6: CID0 | V6: 0.9 | W6: 40 | X6: no | Z6: bound | AA6: False | AB6: required for formal certification | AC6: HIL-R2 | AD6: False | AE6: False | AF6: False | AG6: False | AH6: False | AI6: correctness; robustness; calibration | AJ6: tokens; latency; contamination notes | AK6: hidden/sealed assets; candidate cannot write verifier/acceptance criteria | AL6: development-bound
A7: C-C0-ADVA-B | B7: 1.0 | C7: Unified Intelligence / HIL Framework v1.5.1 (memory-integrated, delivered-correct delegation) | D7: C-Bench | E7: C | F7: C0 | G7: HG0 | I7: advanced_mathematics | J7: advanced_mathematics | K7: T0 | L7: B | M7: C0 Reactive — Advanced Mathematics (B) | N7: Direct pattern-conditioned response on simple problems. Domain: advanced mathematics. Variant B: distribution shift/distractors. | O7: Minimal standardized context/tools; no persistence credit. External oracle owns success. | P7: answer or executable artifact plus compact evidence record | Q7: Externally verified performance consistent with C0; isolate cognition rather than persistence/autonomy. | R7: Hidden answer key/counterexamples/perturbations appropriate to domain. | S7: independent_reference_or_deterministic | T7: H5-H4 | U7: CID0 | V7: 0.9 | W7: 40 | X7: no | Z7: specification-only | AA7: False | AB7: required for formal certification | AC7: HIL-R2 | AD7: False | AE7: False | AF7: False | AG7: False | AH7: False | AI7: correctness; robustness; calibration | AJ7: tokens; latency; contamination notes | AK7: hidden/sealed assets; candidate cannot write verifier/acceptance criteria | AL7: certification-spec
A8: C-C0-CODI-A | B8: 1.0 | C8: Unified Intelligence / HIL Framework v1.5.1 (memory-integrated, delivered-correct delegation) | D8: C-Bench | E8: C | F8: C0 | G8: HG0 | I8: coding | J8: coding | K8: T0 | L8: A | M8: C0 Reactive — Coding (A) | N8: Direct pattern-conditioned response on simple problems. Domain: coding. Variant A: clean controlled condition. | O8: Minimal standardized context/tools; no persistence credit. External oracle owns success. | P8: answer or executable artifact plus compact evidence record | Q8: Externally verified performance consistent with C0; isolate cognition rather than persistence/autonomy. | R8: Hidden answer key/counterexamples/perturbations appropriate to domain. | S8: independent_reference_or_deterministic | T8: H5-H4 | U8: CID0 | V8: 0.9 | W8: 40 | X8: no | Z8: specification-only | AA8: False | AB8: required for formal certification | AC8: HIL-R2 | AD8: False | AE8: False | AF8: False | AG8: False | AH8: False | AI8: correctness; robustness; calibration | AJ8: tokens; latency; contamination notes | AK8: hidden/sealed assets; candidate cannot write verifier/acceptance criteria | AL8: certification-spec
A9: C-C0-CODI-B | B9: 1.0 | C9: Unified Intelligence / HIL Framework v1.5.1 (memory-integrated, delivered-correct delegation) | D9: C-Bench | E9: C | F9: C0 | G9: HG0 | I9: coding | J9: coding | K9: T0 | L9: B | M9: C0 Reactive — Coding (B) | N9: Direct pattern-conditioned response on simple problems. Domain: coding. Variant B: distribution shift/distractors. | O9: Minimal standardized context/tools; no persistence credit. External oracle owns success. | P9: answer or executable artifact plus compact evidence record | Q9: Externally verified performance consistent with C0; isolate cognition rather than persistence/autonomy. | R9: Hidden answer key/counterexamples/perturbations appropriate to domain. | S9: independent_reference_or_deterministic | T9: H5-H4 | U9: CID0 | V9: 0.9 | W9: 40 | X9: no | Z9: specification-only | AA9: False | AB9: required for formal certification | AC9: HIL-R2 | AD9: False | AE9: False | AF9: False | AG9: False | AH9: False | AI9: correctness; robustness; calibration | AJ9: tokens; latency; contamination notes | AK9: hidden/sealed assets; candidate cannot write verifier/acceptance criteria | AL9: certification-spec
A10: C-C0-ABST-A | B10: 1.0 | C10: Unified Intelligence / HIL Framework v1.5.1 (memory-integrated, delivered-correct delegation) | D10: C-Bench | E10: C | F10: C0 | G10: HG0 | I10: abstract_reasoning | J10: abstract_reasoning | K10: T0 | L10: A | M10: C0 Reactive — Abstract Reasoning (A) | N10: Direct pattern-conditioned response on simple problems. Domain: abstract reasoning. Variant A: clean controlled condition. | O10: Minimal standardized context/tools; no persistence credit. External oracle owns success. | P10: answer or executable artifact plus compact evidence record | Q10: Externally verified performance consistent with C0; isolate cognition rather than persistence/autonomy. | R10: Hidden answer key/counterexamples/perturbations appropriate to domain. | S10: independent_reference_or_deterministic | T10: H5-H4 | U10: CID0 | V10: 0.9 | W10: 40 | X10: no | Z10: specification-only | AA10: False | AB10: required for formal certification | AC10: HIL-R2 | AD10: False | AE10: False | AF10: False | AG10: False | AH10: False | AI10: correctness; robustness; calibration | AJ10: tokens; latency; contamination notes | AK10: hidden/sealed assets; candidate cannot write verifier/acceptance criteria | AL10: certification-spec
A11: C-C0-ABST-B | B11: 1.0 | C11: Unified Intelligence / HIL Framework v1.5.1 (memory-integrated, delivered-correct delegation) | D11: C-Bench | E11: C | F11: C0 | G11: HG0 | I11: abstract_reasoning | J11: abstract_reasoning | K11: T0 | L11: B | M11: C0 Reactive — Abstract Reasoning (B) | N11: Direct pattern-conditioned response on simple problems. Domain: abstract reasoning. Variant B: distribution shift/distractors. | O11: Minimal standardized context/tools; no persistence credit. External oracle owns success. | P11: answer or executable artifact plus compact evidence record | Q11: Externally verified performance consistent with C0; isolate cognition rather than persistence/autonomy. | R11: Hidden answer key/counterexamples/perturbations appropriate to domain. | S11: independent_reference_or_deterministic | T11: H5-H4 | U11: CID0 | V11: 0.9 | W11: 40 | X11: no | Z11: specification-only | AA11: False | AB11: required for formal certification | AC11: HIL-R2 | AD11: False | AE11: False | AF11: False | AG11: False | AH11: False | AI11: correctness; robustness; calibration | AJ11: tokens; latency; contamination notes | AK11: hidden/sealed assets; candidate cannot write verifier/acceptance criteria | AL11: certification-spec
A12: C-C0-MULT-A | B12: 1.0 | C12: Unified Intelligence / HIL Framework v1.5.1 (memory-integrated, delivered-correct delegation) | D12: C-Bench | E12: C | F12: C0 | G12: HG0 | I12: multimodal_reasoning | J12: multimodal_reasoning | K12: T0 | L12: A | M12: C0 Reactive — Multimodal Reasoning (A) | N12: Direct pattern-conditioned response on simple problems. Domain: multimodal reasoning. Variant A: clean controlled condition. | O12: Minimal standardized context/tools; no persistence credit. External oracle owns success. | P12: answer or executable artifact plus compact evidence record | Q12: Externally verified performance consistent with C0; isolate cognition rather than persistence/autonomy. | R12: Hidden answer key/counterexamples/perturbations appropriate to domain. | S12: independent_reference_or_deterministic | T12: H5-H4 | U12: CID0 | V12: 0.9 | W12: 40 | X12: no | Z12: specification-only | AA12: False | AB12: required for formal certification | AC12: HIL-R2 | AD12: False | AE12: False | AF12: False | AG12: False | AH12: False | AI12: correctness; robustness; calibration | AJ12: tokens; latency; contamination notes | AK12: hidden/sealed assets; candidate cannot write verifier/acceptance criteria | AL12: certification-spec
A13: C-C0-MULT-B | B13: 1.0 | C13: Unified Intelligence / HIL Framework v1.5.1 (memory-integrated, delivered-correct delegation) | D13: C-Bench | E13: C | F13: C0 | G13: HG0 | I13: multimodal_reasoning | J13: multimodal_reasoning | K13: T0 | L13: B | M13: C0 Reactive — Multimodal Reasoning (B) | N13: Direct pattern-conditioned response on simple problems. Domain: multimodal reasoning. Variant B: distribution shift/distractors. | O13: Minimal standardized context/tools; no persistence credit. External oracle owns success. | P13: answer or executable artifact plus compact evidence record | Q13: Externally verified performance consistent with C0; isolate cognition rather than persistence/autonomy. | R13: Hidden answer key/counterexamples/perturbations appropriate to domain. | S13: independent_reference_or_deterministic | T13: H5-H4 | U13: CID0 | V13: 0.9 | W13: 40 | X13: no | Z13: specification-only | AA13: False | AB13: required for formal certification | AC13: HIL-R2 | AD13: False | AE13: False | AF13: False | AG13: False | AH13: False | AI13: correctness; robustness; calibration | AJ13: tokens; latency; contamination notes | AK13: hidden/sealed assets; candidate cannot write verifier/acceptance criteria | AL13: certification-spec
... A129: C-CΩ-FACT-B | B129: 1.0 | C129: Unified Intelligence / HIL Framework v1.5.1 (memory-integrated, delivered-correct delegation) | D129: C-Bench | E129: C | F129: CΩ | G129: HG0 | I129: factuality_calibration | J129: factuality_calibration | K129: TΩ | L129: B | M129: CΩ Open-Ended — Factuality Calibration (B) | N129: Expand representations and problem classes cognitively reachable. Domain: factuality calibration. Variant B: distribution shift/distractors. | O129: Minimal standardized context/tools; no persistence credit. External oracle owns success. | P129: answer or executable artifact plus compact evidence record | Q129: Externally verified performance consistent with CΩ; isolate cognition rather than persistence/autonomy. | R129: Hidden answer key/counterexamples/perturbations appropriate to domain. | S129: independent_reference_or_deterministic | T129: H5-H4 | U129: CID0 | V129: 0.7 | W129: 24 | X129: no | Z129: specification-only | AA129: False | AB129: required for formal certification | AC129: HIL-R2 | AD129: False | AE129: False | AF129: False | AG129: False | AH129: False | AI129: correctness; robustness; calibration | AJ129: tokens; latency; contamination notes | AK129: hidden/sealed assets; candidate cannot write verifier/acceptance criteria | AL129: certification-spec
A130: I-I0-TRANSIENT_BA-A | B130: 1.0 | C130: Unified Intelligence / HIL Framework v1.5.1 (memory-integrated, delivered-correct delegation) | D130: I-Bench | E130: I | F130: I0 | G130: HG0 | H130: U0 | I130: transient_baseline | J130: longitudinal_individual | K130: T0 | L130: A | M130: I0 — Transient Baseline (A) | N130: No persistent evolving cognition; solve within one episode. Variant A is a clean longitudinal condition. | O130: Multi-session harness with real process/context discontinuity where persistence is claimed; do not replay full transcript as a substitute for memory. | P130: state/evidence artifact plus task outcome; exact provenance record when applicable | Q130: Externally verified I0 behavior with all lower I-level retention; long context alone cannot substitute for persistent memory. | R130: Hidden later queries, withheld updates, sealed replay or external promotion oracle according to level. | S130: independent_reference_or_deterministic | T130: H1 | U130: CID1 | V130: 0.85 | W130: 12 | X130: no | Y130: all lower I levels | Z130: specification-only | AA130: False | AB130: required for formal certification | AC130: HIL-R2 | AD130: False | AE130: False | AF130: False | AG130: False | AH130: False | AI130: task correctness; memory integrity; transfer/change evidence; retention | AJ130: retrieval precision/recall; contradiction; provenance; regression; cost | AK130: hidden/sealed assets; candidate cannot write verifier/acceptance criteria | AL130: certification-spec
A131: I-I0-TRANSIENT_BA-B | B131: 1.0 | C131: Unified Intelligence / HIL Framework v1.5.1 (memory-integrated, delivered-correct delegation) | D131: I-Bench | E131: I | F131: I0 | G131: HG0 | H131: U0 | I131: transient_baseline | J131: longitudinal_individual | K131: T0 | L131: B | M131: I0 — Transient Baseline (B) | N131: No persistent evolving cognition; solve within one episode. Variant B adds conflicting/stale/distractor evidence or distribution shift. | O131: Multi-session harness with real process/context discontinuity where persistence is claimed; do not replay full transcript as a substitute for memory. | P131: state/evidence artifact plus task outcome; exact provenance record when applicable | Q131: Externally verified I0 behavior with all lower I-level retention; long context alone cannot substitute for persistent memory. | R131: Hidden later queries, withheld updates, sealed replay or external promotion oracle according to level. | S131: independent_reference_or_deterministic | T131: H1 | U131: CID1 | V131: 0.85 | W131: 12 | X131: no | Y131: all lower I levels | Z131: specification-only | AA131: False | AB131: required for formal certification | AC131: HIL-R2 | AD131: False | AE131: False | AF131: False | AG131: False | AH131: False | AI131: task correctness; memory integrity; transfer/change evidence; retention | AJ131: retrieval precision/recall; contradiction; provenance; regression; cost | AK131: hidden/sealed assets; candidate cannot write verifier/acceptance criteria | AL131: certification-spec
A132: I-I0-NO_PERSISTEN-A | B132: 1.0 | C132: Unified Intelligence / HIL Framework v1.5.1 (memory-integrated, delivered-correct delegation) | D132: I-Bench | E132: I | F132: I0 | G132: HG0 | H132: U0 | I132: no_persistence_control | J132: longitudinal_individual | K132: T0 | L132: A | M132: I0 — No Persistence Control (A) | N132: Restart erases state unless externally re-supplied. Variant A is a clean longitudinal condition. | O132: Multi-session harness with real process/context discontinuity where persistence is claimed; do not replay full transcript as a substitute for memory. | P132: state/evidence artifact plus task outcome; exact provenance record when applicable | Q132: Externally verified I0 behavior with all lower I-level retention; long context alone cannot substitute for persistent memory. | R132: Hidden later queries, withheld updates, sealed replay or external promotion oracle according to level. | S132: independent_reference_or_deterministic | T132: H1 | U132: CID1 | V132: 0.85 | W132: 12 | X132: no | Y132: all lower I levels | Z132: specification-only | AA132: False | AB132: required for formal certification | AC132: HIL-R2 | AD132: False | AE132: False | AF132: False | AG132: False | AH132: False | AI132: task correctness; memory integrity; transfer/change evidence; retention | AJ132: retrieval precision/recall; contradiction; provenance; regression; cost | AK132: hidden/sealed assets; candidate cannot write verifier/acceptance criteria | AL132: certification-spec
A133: I-I0-NO_PERSISTEN-B | B133: 1.0 | C133: Unified Intelligence / HIL Framework v1.5.1 (memory-integrated, delivered-correct delegation) | D133: I-Bench | E133: I | F133: I0 | G133: HG0 | H133: U0 | I133: no_persistence_control | J133: longitudinal_individual | K133: T0 | L133: B | M133: I0 — No Persistence Control (B) | N133: Restart erases state unless externally re-supplied. Variant B adds conflicting/stale/distractor evidence or distribution shift. | O133: Multi-session harness with real process/context discontinuity where persistence is claimed; do not replay full transcript as a substitute for memory. | P133: state/evidence artifact plus task outcome; exact provenance record when applicable | Q133: Externally verified I0 behavior with all lower I-level retention; long context alone cannot substitute for persistent memory. | R133: Hidden later queries, withheld updates, sealed replay or external promotion oracle according to level. | S133: independent_reference_or_deterministic | T133: H1 | U133: CID1 | V133: 0.85 | W133: 12 | X133: no | Y133: all lower I levels | Z133: specification-only | AA133: False | AB133: required for formal certification | AC133: HIL-R2 | AD133: False | AE133: False | AF133: False | AG133: False | AH133: False | AI133: task correctness; memory integrity; transfer/change evidence; retention | AJ133: retrieval precision/recall; contradiction; provenance; regression; cost | AK133: hidden/sealed assets; candidate cannot write verifier/acceptance criteria | AL133: certification-spec
A134: I-I0-BOUNDED_CONT-A | B134: 1.0 | C134: Unified Intelligence / HIL Framework v1.5.1 (memory-integrated, delivered-correct delegation) | D134: I-Bench | E134: I | F134: I0 | G134: HG0 | H134: U0 | I134: bounded_context_operation | J134: longitudinal_individual | K134: T0 | L134: A | M134: I0 — Bounded Context Operation (A) | N134: Operate only on active context. Variant A is a clean longitudinal condition. | O134: Multi-session harness with real process/context discontinuity where persistence is claimed; do not replay full transcript as a substitute for memory. | P134: state/evidence artifact plus task outcome; exact provenance record when applicable | Q134: Externally verified I0 behavior with all lower I-level retention; long context alone cannot substitute for persistent memory. | R134: Hidden later queries, withheld updates, sealed replay or external promotion oracle according to level. | S134: independent_reference_or_deterministic | T134: H1 | U134: CID1 | V134: 0.85 | W134: 12 | X134: no | Y134: all lower I levels | Z134: specification-only | AA134: False | AB134: required for formal certification | AC134: HIL-R2 | AD134: False | AE134: False | AF134: False | AG134: False | AH134: False | AI134: task correctness; memory integrity; transfer/change evidence; retention | AJ134: retrieval precision/recall; contradiction; provenance; regression; cost | AK134: hidden/sealed assets; candidate cannot write verifier/acceptance criteria | AL134: certification-spec
A135: I-I0-BOUNDED_CONT-B | B135: 1.0 | C135: Unified Intelligence / HIL Framework v1.5.1 (memory-integrated, delivered-correct delegation) | D135: I-Bench | E135: I | F135: I0 | G135: HG0 | H135: U0 | I135: bounded_context_operation | J135: longitudinal_individual | K135: T0 | L135: B | M135: I0 — Bounded Context Operation (B) | N135: Operate only on active context. Variant B adds conflicting/stale/distractor evidence or distribution shift. | O135: Multi-session harness with real process/context discontinuity where persistence is claimed; do not replay full transcript as a substitute for memory. | P135: state/evidence artifact plus task outcome; exact provenance record when applicable | Q135: Externally verified I0 behavior with all lower I-level retention; long context alone cannot substitute for persistent memory. | R135: Hidden later queries, withheld updates, sealed replay or external promotion oracle according to level. | S135: independent_reference_or_deterministic | T135: H1 | U135: CID1 | V135: 0.85 | W135: 12 | X135: no | Y135: all lower I levels | Z135: specification-only | AA135: False | AB135: required for formal certification | AC135: HIL-R2 | AD135: False | AE135: False | AF135: False | AG135: False | AH135: False | AI135: task correctness; memory integrity; transfer/change evidence; retention | AJ135: retrieval precision/recall; contradiction; provenance; regression; cost | AK135: hidden/sealed assets; candidate cannot write verifier/acceptance criteria | AL135: certification-spec
A136: I-I0-EPHEMERAL_TO-A | B136: 1.0 | C136: Unified Intelligence / HIL Framework v1.5.1 (memory-integrated, delivered-correct delegation) | D136: I-Bench | E136: I | F136: I0 | G136: HG0 | H136: U0 | I136: ephemeral_tool_use | J136: longitudinal_individual | K136: T0 | L136: A | M136: I0 — Ephemeral Tool Use (A) | N136: Use tools without durable learning. Variant A is a clean longitudinal condition. | O136: Multi-session harness with real process/context discontinuity where persistence is claimed; do not replay full transcript as a substitute for memory. | P136: state/evidence artifact plus task outcome; exact provenance record when applicable | Q136: Externally verified I0 behavior with all lower I-level retention; long context alone cannot substitute for persistent memory. | R136: Hidden later queries, withheld updates, sealed replay or external promotion oracle according to level. | S136: independent_reference_or_deterministic | T136: H1 | U136: CID1 | V136: 0.85 | W136: 12 | X136: no | Y136: all lower I levels | Z136: specification-only | AA136: False | AB136: required for formal certification | AC136: HIL-R2 | AD136: False | AE136: False | AF136: False | AG136: False | AH136: False | AI136: task correctness; memory integrity; transfer/change evidence; retention | AJ136: retrieval precision/recall; contradiction; provenance; regression; cost | AK136: hidden/sealed assets; candidate cannot write verifier/acceptance criteria | AL136: certification-spec
A137: I-I0-EPHEMERAL_TO-B | B137: 1.0 | C137: Unified Intelligence / HIL Framework v1.5.1 (memory-integrated, delivered-correct delegation) | D137: I-Bench | E137: I | F137: I0 | G137: HG0 | H137: U0 | I137: ephemeral_tool_use | J137: longitudinal_individual | K137: T0 | L137: B | M137: I0 — Ephemeral Tool Use (B) | N137: Use tools without durable learning. Variant B adds conflicting/stale/distractor evidence or distribution shift. | O137: Multi-session harness with real process/context discontinuity where persistence is claimed; do not replay full transcript as a substitute for memory. | P137: state/evidence artifact plus task outcome; exact provenance record when applicable | Q137: Externally verified I0 behavior with all lower I-level retention; long context alone cannot substitute for persistent memory. | R137: Hidden later queries, withheld updates, sealed replay or external promotion oracle according to level. | S137: independent_reference_or_deterministic | T137: H1 | U137: CID1 | V137: 0.85 | W137: 12 | X137: no | Y137: all lower I levels | Z137: specification-only | AA137: False | AB137: required for formal certification | AC137: HIL-R2 | AD137: False | AE137: False | AF137: False | AG137: False | AH137: False | AI137: task correctness; memory integrity; transfer/change evidence; retention | AJ137: retrieval precision/recall; contradiction; provenance; regression; cost | AK137: hidden/sealed assets; candidate cannot write verifier/acceptance criteria | AL137: certification-spec
A138: I-I0-SAME_SESSION-A | B138: 1.0 | C138: Unified Intelligence / HIL Framework v1.5.1 (memory-integrated, delivered-correct delegation) | D138: I-Bench | E138: I | F138: I0 | G138: HG0 | H138: U0 | I138: same_session_repeatability | J138: longitudinal_individual | K138: T0 | L138: A | M138: I0 — Same Session Repeatability (A) | N138: Repeat within session without claiming learning. Variant A is a clean longitudinal condition. | O138: Multi-session harness with real process/context discontinuity where persistence is claimed; do not replay full transcript as a substitute for memory. | P138: state/evidence artifact plus task outcome; exact provenance record when applicable | Q138: Externally verified I0 behavior with all lower I-level retention; long context alone cannot substitute for persistent memory. | R138: Hidden later queries, withheld updates, sealed replay or external promotion oracle according to level. | S138: independent_reference_or_deterministic | T138: H1 | U138: CID1 | V138: 0.85 | W138: 12 | X138: no | Y138: all lower I levels | Z138: specification-only | AA138: False | AB138: required for formal certification | AC138: HIL-R2 | AD138: False | AE138: False | AF138: False | AG138: False | AH138: False | AI138: task correctness; memory integrity; transfer/change evidence; retention | AJ138: retrieval precision/recall; contradiction; provenance; regression; cost | AK138: hidden/sealed assets; candidate cannot write verifier/acceptance criteria | AL138: certification-spec
A139: I-I0-SAME_SESSION-B | B139: 1.0 | C139: Unified Intelligence / HIL Framework v1.5.1 (memory-integrated, delivered-correct delegation) | D139: I-Bench | E139: I | F139: I0 | G139: HG0 | H139: U0 | I139: same_session_repeatability | J139: longitudinal_individual | K139: T0 | L139: B | M139: I0 — Same Session Repeatability (B) | N139: Repeat within session without claiming learning. Variant B adds conflicting/stale/distractor evidence or distribution shift. | O139: Multi-session harness with real process/context discontinuity where persistence is claimed; do not replay full transcript as a substitute for memory. | P139: state/evidence artifact plus task outcome; exact provenance record when applicable | Q139: Externally verified I0 behavior with all lower I-level retention; long context alone cannot substitute for persistent memory. | R139: Hidden later queries, withheld updates, sealed replay or external promotion oracle according to level. | S139: independent_reference_or_deterministic | T139: H1 | U139: CID1 | V139: 0.85 | W139: 12 | X139: no | Y139: all lower I levels | Z139: specification-only | AA139: False | AB139: required for formal certification | AC139: HIL-R2 | AD139: False | AE139: False | AF139: False | AG139: False | AH139: False | AI139: task correctness; memory integrity; transfer/change evidence; retention | AJ139: retrieval precision/recall; contradiction; provenance; regression; cost | AK139: hidden/sealed assets; candidate cannot write verifier/acceptance criteria | AL139: certification-spec
A140: I-I0-STATE_ABSENC-A | B140: 1.0 | C140: Unified Intelligence / HIL Framework v1.5.1 (memory-integrated, delivered-correct delegation) | D140: I-Bench | E140: I | F140: I0 | G140: HG0 | H140: U0 | I140: state_absence_detection | J140: longitudinal_individual | K140: T0 | L140: A | M140: I0 — State Absence Detection (A) | N140: Expose absence of durable state. Variant A is a clean longitudinal condition. | O140: Multi-session harness with real process/context discontinuity where persistence is claimed; do not replay full transcript as a substitute for memory. | P140: state/evidence artifact plus task outcome; exact provenance record when applicable | Q140: Externally verified I0 behavior with all lower I-level retention; long context alone cannot substitute for persistent memory. | R140: Hidden later queries, withheld updates, sealed replay or external promotion oracle according to level. | S140: independent_reference_or_deterministic | T140: H1 | U140: CID1 | V140: 0.85 | W140: 12 | X140: no | Y140: all lower I levels | Z140: specification-only | AA140: False | AB140: required for formal certification | AC140: HIL-R2 | AD140: False | AE140: False | AF140: False | AG140: False | AH140: False | AI140: task correctness; memory integrity; transfer/change evidence; retention | AJ140: retrieval precision/recall; contradiction; provenance; regression; cost | AK140: hidden/sealed assets; candidate cannot write verifier/acceptance criteria | AL140: certification-spec
A141: I-I0-STATE_ABSENC-B | B141: 1.0 | C141: Unified Intelligence / HIL Framework v1.5.1 (memory-integrated, delivered-correct delegation) | D141: I-Bench | E141: I | F141: I0 | G141: HG0 | H141: U0 | I141: state_absence_detection | J141: longitudinal_individual | K141: T0 | L141: B | M141: I0 — State Absence Detection (B) | N141: Expose absence of durable state. Variant B adds conflicting/stale/distractor evidence or distribution shift. | O141: Multi-session harness with real process/context discontinuity where persistence is claimed; do not replay full transcript as a substitute for memory. | P141: state/evidence artifact plus task outcome; exact provenance record when applicable | Q141: Externally verified I0 behavior with all lower I-level retention; long context alone cannot substitute for persistent memory. | R141: Hidden later queries, withheld updates, sealed replay or external promotion oracle according to level. | S141: independent_reference_or_deterministic | T141: H1 | U141: CID1 | V141: 0.85 | W141: 12 | X141: no | Y141: all lower I levels | Z141: specification-only | AA141: False | AB141: required for formal certification | AC141: HIL-R2 | AD141: False | AE141: False | AF141: False | AG141: False | AH141: False | AI141: task correctness; memory integrity; transfer/change evidence; retention | AJ141: retrieval precision/recall; contradiction; provenance; regression; cost | AK141: hidden/sealed assets; candidate cannot write verifier/acceptance criteria | AL141: certification-spec
... A407: SA-SAΩ-OPEN_ENDED_-B | B407: 1.0 | C407: Unified Intelligence / HIL Framework v1.5.1 (memory-integrated, delivered-correct delegation) | D407: SA-Bench | E407: SA | F407: SAΩ | G407: HGΩ | H407: UΩ | I407: open_ended_self_model | J407: self_model | K407: TΩ | L407: B | M407: SAΩ — Open Ended Self Model (B) | N407: Measure evidence-grounded self-model behavior: open ended self model. Self-description without machine-grounded state does not count. | O407: Ground-truth self/environment fields externally controlled; some cases include stale or conflicting textual cues. | P407: structured self-model judgment + evidence refs + action/escalation choice | Q407: Correct externally grounded behavior consistent with SAΩ; no credit for unsupported narrative confidence. | R407: Machine-observable state differs from tempting textual cues in some cases. | S407: independent_reference_or_deterministic | T407: H1 | U407: CID1 | V407: 0.75 | W407: 10 | X407: no | Y407: all lower SA levels | Z407: specification-only | AA407: False | AB407: required for formal certification | AC407: HIL-R2 | AD407: True | AE407: False | AF407: False | AG407: False | AH407: True | AI407: state truth; calibration; causal attribution; change prediction | AJ407: unsupported-claim; stale-state; authority errors; escalation quality | AK407: hidden/sealed assets; candidate cannot write verifier/acceptance criteria | AL407: certification-spec
A408: DI-T0-SOFTWARE-A | B408: 1.0 | C408: Unified Intelligence / HIL Framework v1.5.1 (memory-integrated, delivered-correct delegation) | D408: DI-Bench | E408: DI | F408: T0 | G408: HG0-HGΩ | I408: delegation_surface | J408: software_engineering | K408: T0 | L408: A | M408: T0 Atomic — Software Engineering (A) | N408: Complete a software engineering task at T0: Single obvious operation; procedure explicit. Variant A: clean baseline. | O408: Run under each H0-H5 budget. Delivery/acceptance and external verifier verdict logged separately. | P408: task artifact + evidence log + delivery status | Q408: Delivered-and-correct under external verifier; false completion, held-back invalid, false rejection, CID and human minutes recorded. | R408: Hidden reference/sealed environment/deterministic oracle; upper bands require hidden mechanisms or dynamic events. | S408: independent_reference_or_deterministic | T408: H0-H5 matrix | U408: CID budget determined by H condition | V408: 0.95 | W408: 40 | X408: yes for harness-rung comparisons that do not alter executor request | Z408: specification-only | AA408: False | AB408: required for formal certification | AC408: HIL-R2 | AD408: False | AE408: False | AF408: False | AG408: False | AH408: False | AI408: S_del(T,H); F(H,p); false_completion; false_rejection; CID; human minutes | AJ408: attempts; VR; tokens; calls; tools; latency; cost | AK408: hidden/sealed assets; candidate cannot write verifier/acceptance criteria | AL408: certification-spec
A409: DI-T0-SOFTWARE-B | B409: 1.0 | C409: Unified Intelligence / HIL Framework v1.5.1 (memory-integrated, delivered-correct delegation) | D409: DI-Bench | E409: DI | F409: T0 | G409: HG0-HGΩ | I409: delegation_surface | J409: software_engineering | K409: T0 | L409: B | M409: T0 Atomic — Software Engineering (B) | N409: Complete a software engineering task at T0: Single obvious operation; procedure explicit. Variant B: dynamic change/distractor/recovery event. | O409: Run under each H0-H5 budget. Delivery/acceptance and external verifier verdict logged separately. | P409: task artifact + evidence log + delivery status | Q409: Delivered-and-correct under external verifier; false completion, held-back invalid, false rejection, CID and human minutes recorded. | R409: Hidden reference/sealed environment/deterministic oracle; upper bands require hidden mechanisms or dynamic events. | S409: independent_reference_or_deterministic | T409: H0-H5 matrix | U409: CID budget determined by H condition | V409: 0.95 | W409: 40 | X409: yes for harness-rung comparisons that do not alter executor request | Z409: specification-only | AA409: False | AB409: required for formal certification | AC409: HIL-R2 | AD409: False | AE409: False | AF409: False | AG409: False | AH409: False | AI409: S_del(T,H); F(H,p); false_completion; false_rejection; CID; human minutes | AJ409: attempts; VR; tokens; calls; tools; latency; cost | AK409: hidden/sealed assets; candidate cannot write verifier/acceptance criteria | AL409: certification-spec
A410: DI-T0-DATA_ANA-A | B410: 1.0 | C410: Unified Intelligence / HIL Framework v1.5.1 (memory-integrated, delivered-correct delegation) | D410: DI-Bench | E410: DI | F410: T0 | G410: HG0-HGΩ | I410: delegation_surface | J410: data_analysis | K410: T0 | L410: A | M410: T0 Atomic — Data Analysis (A) | N410: Complete a data analysis task at T0: Single obvious operation; procedure explicit. Variant A: clean baseline. | O410: Run under each H0-H5 budget. Delivery/acceptance and external verifier verdict logged separately. | P410: task artifact + evidence log + delivery status | Q410: Delivered-and-correct under external verifier; false completion, held-back invalid, false rejection, CID and human minutes recorded. | R410: Hidden reference/sealed environment/deterministic oracle; upper bands require hidden mechanisms or dynamic events. | S410: independent_reference_or_deterministic | T410: H0-H5 matrix | U410: CID budget determined by H condition | V410: 0.95 | W410: 40 | X410: yes for harness-rung comparisons that do not alter executor request | Z410: bound | AA410: False | AB410: required for formal certification | AC410: HIL-R2 | AD410: False | AE410: False | AF410: False | AG410: False | AH410: False | AI410: S_del(T,H); F(H,p); false_completion; false_rejection; CID; human minutes | AJ410: attempts; VR; tokens; calls; tools; latency; cost | AK410: hidden/sealed assets; candidate cannot write verifier/acceptance criteria | AL410: development-bound
A411: DI-T0-DATA_ANA-B | B411: 1.0 | C411: Unified Intelligence / HIL Framework v1.5.1 (memory-integrated, delivered-correct delegation) | D411: DI-Bench | E411: DI | F411: T0 | G411: HG0-HGΩ | I411: delegation_surface | J411: data_analysis | K411: T0 | L411: B | M411: T0 Atomic — Data Analysis (B) | N411: Complete a data analysis task at T0: Single obvious operation; procedure explicit. Variant B: dynamic change/distractor/recovery event. | O411: Run under each H0-H5 budget. Delivery/acceptance and external verifier verdict logged separately. | P411: task artifact + evidence log + delivery status | Q411: Delivered-and-correct under external verifier; false completion, held-back invalid, false rejection, CID and human minutes recorded. | R411: Hidden reference/sealed environment/deterministic oracle; upper bands require hidden mechanisms or dynamic events. | S411: independent_reference_or_deterministic | T411: H0-H5 matrix | U411: CID budget determined by H condition | V411: 0.95 | W411: 40 | X411: yes for harness-rung comparisons that do not alter executor request | Z411: specification-only | AA411: False | AB411: required for formal certification | AC411: HIL-R2 | AD411: False | AE411: False | AF411: False | AG411: False | AH411: False | AI411: S_del(T,H); F(H,p); false_completion; false_rejection; CID; human minutes | AJ411: attempts; VR; tokens; calls; tools; latency; cost | AK411: hidden/sealed assets; candidate cannot write verifier/acceptance criteria | AL411: certification-spec
A412: DI-T0-SCIENTIF-A | B412: 1.0 | C412: Unified Intelligence / HIL Framework v1.5.1 (memory-integrated, delivered-correct delegation) | D412: DI-Bench | E412: DI | F412: T0 | G412: HG0-HGΩ | I412: delegation_surface | J412: scientific_research | K412: T0 | L412: A | M412: T0 Atomic — Scientific Research (A) | N412: Complete a scientific research task at T0: Single obvious operation; procedure explicit. Variant A: clean baseline. | O412: Run under each H0-H5 budget. Delivery/acceptance and external verifier verdict logged separately. | P412: task artifact + evidence log + delivery status | Q412: Delivered-and-correct under external verifier; false completion, held-back invalid, false rejection, CID and human minutes recorded. | R412: Hidden reference/sealed environment/deterministic oracle; upper bands require hidden mechanisms or dynamic events. | S412: independent_reference_or_deterministic | T412: H0-H5 matrix | U412: CID budget determined by H condition | V412: 0.95 | W412: 40 | X412: yes for harness-rung comparisons that do not alter executor request | Z412: specification-only | AA412: False | AB412: required for formal certification | AC412: HIL-R2 | AD412: False | AE412: False | AF412: False | AG412: False | AH412: False | AI412: S_del(T,H); F(H,p); false_completion; false_rejection; CID; human minutes | AJ412: attempts; VR; tokens; calls; tools; latency; cost | AK412: hidden/sealed assets; candidate cannot write verifier/acceptance criteria | AL412: certification-spec
A413: DI-T0-SCIENTIF-B | B413: 1.0 | C413: Unified Intelligence / HIL Framework v1.5.1 (memory-integrated, delivered-correct delegation) | D413: DI-Bench | E413: DI | F413: T0 | G413: HG0-HGΩ | I413: delegation_surface | J413: scientific_research | K413: T0 | L413: B | M413: T0 Atomic — Scientific Research (B) | N413: Complete a scientific research task at T0: Single obvious operation; procedure explicit. Variant B: dynamic change/distractor/recovery event. | O413: Run under each H0-H5 budget. Delivery/acceptance and external verifier verdict logged separately. | P413: task artifact + evidence log + delivery status | Q413: Delivered-and-correct under external verifier; false completion, held-back invalid, false rejection, CID and human minutes recorded. | R413: Hidden reference/sealed environment/deterministic oracle; upper bands require hidden mechanisms or dynamic events. | S413: independent_reference_or_deterministic | T413: H0-H5 matrix | U413: CID budget determined by H condition | V413: 0.95 | W413: 40 | X413: yes for harness-rung comparisons that do not alter executor request | Z413: specification-only | AA413: False | AB413: required for formal certification | AC413: HIL-R2 | AD413: False | AE413: False | AF413: False | AG413: False | AH413: False | AI413: S_del(T,H); F(H,p); false_completion; false_rejection; CID; human minutes | AJ413: attempts; VR; tokens; calls; tools; latency; cost | AK413: hidden/sealed assets; candidate cannot write verifier/acceptance criteria | AL413: certification-spec
A414: DI-T0-PLANNING-A | B414: 1.0 | C414: Unified Intelligence / HIL Framework v1.5.1 (memory-integrated, delivered-correct delegation) | D414: DI-Bench | E414: DI | F414: T0 | G414: HG0-HGΩ | I414: delegation_surface | J414: planning_operations | K414: T0 | L414: A | M414: T0 Atomic — Planning Operations (A) | N414: Complete a planning operations task at T0: Single obvious operation; procedure explicit. Variant A: clean baseline. | O414: Run under each H0-H5 budget. Delivery/acceptance and external verifier verdict logged separately. | P414: task artifact + evidence log + delivery status | Q414: Delivered-and-correct under external verifier; false completion, held-back invalid, false rejection, CID and human minutes recorded. | R414: Hidden reference/sealed environment/deterministic oracle; upper bands require hidden mechanisms or dynamic events. | S414: independent_reference_or_deterministic | T414: H0-H5 matrix | U414: CID budget determined by H condition | V414: 0.95 | W414: 40 | X414: yes for harness-rung comparisons that do not alter executor request | Z414: specification-only | AA414: False | AB414: required for formal certification | AC414: HIL-R2 | AD414: False | AE414: False | AF414: False | AG414: False | AH414: False | AI414: S_del(T,H); F(H,p); false_completion; false_rejection; CID; human minutes | AJ414: attempts; VR; tokens; calls; tools; latency; cost | AK414: hidden/sealed assets; candidate cannot write verifier/acceptance criteria | AL414: certification-spec
A415: DI-T0-PLANNING-B | B415: 1.0 | C415: Unified Intelligence / HIL Framework v1.5.1 (memory-integrated, delivered-correct delegation) | D415: DI-Bench | E415: DI | F415: T0 | G415: HG0-HGΩ | I415: delegation_surface | J415: planning_operations | K415: T0 | L415: B | M415: T0 Atomic — Planning Operations (B) | N415: Complete a planning operations task at T0: Single obvious operation; procedure explicit. Variant B: dynamic change/distractor/recovery event. | O415: Run under each H0-H5 budget. Delivery/acceptance and external verifier verdict logged separately. | P415: task artifact + evidence log + delivery status | Q415: Delivered-and-correct under external verifier; false completion, held-back invalid, false rejection, CID and human minutes recorded. | R415: Hidden reference/sealed environment/deterministic oracle; upper bands require hidden mechanisms or dynamic events. | S415: independent_reference_or_deterministic | T415: H0-H5 matrix | U415: CID budget determined by H condition | V415: 0.95 | W415: 40 | X415: yes for harness-rung comparisons that do not alter executor request | Z415: specification-only | AA415: False | AB415: required for formal certification | AC415: HIL-R2 | AD415: False | AE415: False | AF415: False | AG415: False | AH415: False | AI415: S_del(T,H); F(H,p); false_completion; false_rejection; CID; human minutes | AJ415: attempts; VR; tokens; calls; tools; latency; cost | AK415: hidden/sealed assets; candidate cannot write verifier/acceptance criteria | AL415: certification-spec
A416: DI-T0-DOCUMENT-A | B416: 1.0 | C416: Unified Intelligence / HIL Framework v1.5.1 (memory-integrated, delivered-correct delegation) | D416: DI-Bench | E416: DI | F416: T0 | G416: HG0-HGΩ | I416: delegation_surface | J416: document_workflow | K416: T0 | L416: A | M416: T0 Atomic — Document Workflow (A) | N416: Complete a document workflow task at T0: Single obvious operation; procedure explicit. Variant A: clean baseline. | O416: Run under each H0-H5 budget. Delivery/acceptance and external verifier verdict logged separately. | P416: task artifact + evidence log + delivery status | Q416: Delivered-and-correct under external verifier; false completion, held-back invalid, false rejection, CID and human minutes recorded. | R416: Hidden reference/sealed environment/deterministic oracle; upper bands require hidden mechanisms or dynamic events. | S416: independent_reference_or_deterministic | T416: H0-H5 matrix | U416: CID budget determined by H condition | V416: 0.95 | W416: 40 | X416: yes for harness-rung comparisons that do not alter executor request | Z416: bound | AA416: False | AB416: required for formal certification | AC416: HIL-R2 | AD416: False | AE416: False | AF416: False | AG416: False | AH416: False | AI416: S_del(T,H); F(H,p); false_completion; false_rejection; CID; human minutes | AJ416: attempts; VR; tokens; calls; tools; latency; cost | AK416: hidden/sealed assets; candidate cannot write verifier/acceptance criteria | AL416: development-bound
A417: DI-T0-DOCUMENT-B | B417: 1.0 | C417: Unified Intelligence / HIL Framework v1.5.1 (memory-integrated, delivered-correct delegation) | D417: DI-Bench | E417: DI | F417: T0 | G417: HG0-HGΩ | I417: delegation_surface | J417: document_workflow | K417: T0 | L417: B | M417: T0 Atomic — Document Workflow (B) | N417: Complete a document workflow task at T0: Single obvious operation; procedure explicit. Variant B: dynamic change/distractor/recovery event. | O417: Run under each H0-H5 budget. Delivery/acceptance and external verifier verdict logged separately. | P417: task artifact + evidence log + delivery status | Q417: Delivered-and-correct under external verifier; false completion, held-back invalid, false rejection, CID and human minutes recorded. | R417: Hidden reference/sealed environment/deterministic oracle; upper bands require hidden mechanisms or dynamic events. | S417: independent_reference_or_deterministic | T417: H0-H5 matrix | U417: CID budget determined by H condition | V417: 0.95 | W417: 40 | X417: yes for harness-rung comparisons that do not alter executor request | Z417: specification-only | AA417: False | AB417: required for formal certification | AC417: HIL-R2 | AD417: False | AE417: False | AF417: False | AG417: False | AH417: False | AI417: S_del(T,H); F(H,p); false_completion; false_rejection; CID; human minutes | AJ417: attempts; VR; tokens; calls; tools; latency; cost | AK417: hidden/sealed assets; candidate cannot write verifier/acceptance criteria | AL417: certification-spec
A418: DI-T0-TOOL_CAL-A | B418: 1.0 | C418: Unified Intelligence / HIL Framework v1.5.1 (memory-integrated, delivered-correct delegation) | D418: DI-Bench | E418: DI | F418: T0 | G418: HG0-HGΩ | I418: delegation_surface | J418: tool_calling | K418: T0 | L418: A | M418: T0 Atomic — Tool Calling (A) | N418: Complete a tool calling task at T0: Single obvious operation; procedure explicit. Variant A: clean baseline. | O418: Run under each H0-H5 budget. Delivery/acceptance and external verifier verdict logged separately. | P418: task artifact + evidence log + delivery status | Q418: Delivered-and-correct under external verifier; false completion, held-back invalid, false rejection, CID and human minutes recorded. | R418: Hidden reference/sealed environment/deterministic oracle; upper bands require hidden mechanisms or dynamic events. | S418: independent_reference_or_deterministic | T418: H0-H5 matrix | U418: CID budget determined by H condition | V418: 0.95 | W418: 40 | X418: yes for harness-rung comparisons that do not alter executor request | Z418: specification-only | AA418: False | AB418: required for formal certification | AC418: HIL-R2 | AD418: False | AE418: False | AF418: False | AG418: False | AH418: False | AI418: S_del(T,H); F(H,p); false_completion; false_rejection; CID; human minutes | AJ418: attempts; VR; tokens; calls; tools; latency; cost | AK418: hidden/sealed assets; candidate cannot write verifier/acceptance criteria | AL418: certification-spec
A419: DI-T0-TOOL_CAL-B | B419: 1.0 | C419: Unified Intelligence / HIL Framework v1.5.1 (memory-integrated, delivered-correct delegation) | D419: DI-Bench | E419: DI | F419: T0 | G419: HG0-HGΩ | I419: delegation_surface | J419: tool_calling | K419: T0 | L419: B | M419: T0 Atomic — Tool Calling (B) | N419: Complete a tool calling task at T0: Single obvious operation; procedure explicit. Variant B: dynamic change/distractor/recovery event. | O419: Run under each H0-H5 budget. Delivery/acceptance and external verifier verdict logged separately. | P419: task artifact + evidence log + delivery status | Q419: Delivered-and-correct under external verifier; false completion, held-back invalid, false rejection, CID and human minutes recorded. | R419: Hidden reference/sealed environment/deterministic oracle; upper bands require hidden mechanisms or dynamic events. | S419: independent_reference_or_deterministic | T419: H0-H5 matrix | U419: CID budget determined by H condition | V419: 0.95 | W419: 40 | X419: yes for harness-rung comparisons that do not alter executor request | Z419: specification-only | AA419: False | AB419: required for formal certification | AC419: HIL-R2 | AD419: False | AE419: False | AF419: False | AG419: False | AH419: False | AI419: S_del(T,H); F(H,p); false_completion; false_rejection; CID; human minutes | AJ419: attempts; VR; tokens; calls; tools; latency; cost | AK419: hidden/sealed assets; candidate cannot write verifier/acceptance criteria | AL419: certification-spec
